<mujoco model="ur3e_rg2">
  <compiler angle="radian"/>

  <asset>
    <mesh name="base" content_type="model/stl" file="/opt/ros/humble/share/ur_description/meshes/ur3e/collision/base.stl"/>
    <mesh name="shoulder" content_type="model/stl" file="/opt/ros/humble/share/ur_description/meshes/ur3e/collision/shoulder.stl"/>
    <mesh name="upperarm" content_type="model/stl" file="/opt/ros/humble/share/ur_description/meshes/ur3e/collision/upperarm.stl"/>
    <mesh name="forearm" content_type="model/stl" file="/opt/ros/humble/share/ur_description/meshes/ur3e/collision/forearm.stl"/>
    <mesh name="wrist1" content_type="model/stl" file="/opt/ros/humble/share/ur_description/meshes/ur3e/collision/wrist1.stl"/>
    <mesh name="wrist2" content_type="model/stl" file="/opt/ros/humble/share/ur_description/meshes/ur3e/collision/wrist2.stl"/>
    <mesh name="wrist3" content_type="model/stl" file="/opt/ros/humble/share/ur_description/meshes/ur3e/collision/wrist3.stl"/>
    <mesh name="base_link" content_type="model/stl" file="/home/john/git/HoloAssist-AI/ur3e_rl_ws/install/ur3e_gazebo_sim/share/ur3e_gazebo_sim/meshes/rg2/collision/base_link.stl"/>
    <mesh name="outer_knuckle" content_type="model/stl" file="/home/john/git/HoloAssist-AI/ur3e_rl_ws/install/ur3e_gazebo_sim/share/ur3e_gazebo_sim/meshes/rg2/collision/outer_knuckle.stl"/>
    <mesh name="inner_knuckle" content_type="model/stl" file="/home/john/git/HoloAssist-AI/ur3e_rl_ws/install/ur3e_gazebo_sim/share/ur3e_gazebo_sim/meshes/rg2/collision/inner_knuckle.stl"/>
    <mesh name="inner_finger" content_type="model/stl" file="/home/john/git/HoloAssist-AI/ur3e_rl_ws/install/ur3e_gazebo_sim/share/ur3e_gazebo_sim/meshes/rg2/collision/inner_finger.stl"/>
  </asset>

  <worldbody>
    <body name="base_link" pos="0 0 1.1" quat="0 0 0 1">
      <body name="base_link_inertia" quat="0 0 0 1">
        <inertial pos="0 0 0" quat="0.5 0.5 -0.5 0.5" mass="2" diaginertia="0.005625 0.00305317 0.00305317"/>
        <geom pos="0 0 0" quat="0 0 0 1" type="mesh" mesh="base"/>
        <body name="shoulder_link" pos="0 0 0.15185">
          <inertial pos="0 0 -0.02" quat="0.824382 0.56456 0.0308962 -0.0266815" mass="1.98" diaginertia="0.00276682 0.00263413 0.00207745"/>
          <joint name="shoulder_pan_joint" pos="0 0 0" axis="0 0 1" range="-6.28319 6.28319" actuatorfrcrange="-54 54"/>
          <geom quat="0 0 0 1" type="mesh" mesh="shoulder"/>
          <body name="upper_arm_link" quat="0.707107 0.707107 0 0">
            <inertial pos="-0.11355 0 0.1157" quat="0.511541 0.487878 0.493562 0.506653" mass="3.4445" diaginertia="0.0460286 0.0449496 0.00420725"/>
            <joint name="shoulder_lift_joint" pos="0 0 0" axis="0 0 1" range="-6.28319 6.28319" actuatorfrcrange="-54 54"/>
            <geom pos="0 0 0.12" quat="0.5 0.5 -0.5 -0.5" type="mesh" mesh="upperarm"/>
            <body name="forearm_link" pos="-0.24355 0 0">
              <inertial pos="-0.1632 0 0.0238" quat="0.498615 0.501366 0.496974 0.503022" mass="1.437" diaginertia="0.0113396 0.0110896 0.00105099"/>
              <joint name="elbow_joint" pos="0 0 0" axis="0 0 1" range="-3.14159 3.14159" actuatorfrcrange="-28 28"/>
              <geom pos="0 0 0.027" quat="0.5 0.5 -0.5 -0.5" type="mesh" mesh="forearm"/>
              <body name="wrist_1_link" pos="-0.2132 0 0.13105">
                <inertial pos="0 -0.01 0" quat="0.982855 0.184339 -0.00385192 0.00065385" mass="0.871" diaginertia="0.000817416 0.000708389 0.000525695"/>
                <joint name="wrist_1_joint" pos="0 0 0" axis="0 0 1" range="-6.28319 6.28319" actuatorfrcrange="-9 9"/>
                <geom pos="0 0 -0.104" quat="0.707107 0.707107 0 0" type="mesh" mesh="wrist1"/>
                <body name="wrist_2_link" pos="0 -0.08535 -1.75056e-11" quat="0.707107 0.707107 0 0">
                  <inertial pos="0 0.01 0" quat="0.997726 -0.0659421 0.00057165 -0.0139161" mass="0.805" diaginertia="0.000605916 0.000587282 0.000379501"/>
                  <joint name="wrist_2_joint" pos="0 0 0" axis="0 0 1" range="-6.28319 6.28319" actuatorfrcrange="-9 9"/>
                  <geom pos="0 0 -0.08535" quat="1 0 0 0" type="mesh" mesh="wrist2"/>
                  <body name="wrist_3_link" pos="0 0.0921 -1.889e-11" quat="0.707107 -0.707107 0 0">
                    <inertial pos="0 0 -0.02" quat="-0.0596463 0.703375 0.0549048 0.706181" mass="0.261" diaginertia="0.000137102 0.000108615 0.000107983"/>
                    <joint name="wrist_3_joint" pos="0 0 0" axis="0 0 1" actuatorfrcrange="-9 9"/>
                    <geom pos="0 0 -0.0921" quat="0.707107 0.707107 0 0" type="mesh" mesh="wrist3"/>
                    <body name="ft_frame" quat="0 1 0 0"/>
                    <body name="flange" quat="0.5 -0.5 -0.5 -0.5">
                      <body name="tool0" quat="0.5 0.5 0.5 0.5">
                        <body name="onrobot_rg2_base_link">
                          <inertial pos="0 0 0" quat="0.820473 0.339851 -0.17592 0.424708" mass="0.78" diaginertia="0.001002 0.000999 0.000999"/>
                          <geom type="mesh" rgba="0.8 0.8 0.8 1" mesh="base_link"/>
                          <body name="left_outer_knuckle" pos="0 -0.017178 0.125797">
                            <inertial pos="0 0 0" quat="0.820473 0.339851 -0.17592 0.424708" mass="0.05" diaginertia="0.001002 0.000999 0.000999"/>
                            <geom type="mesh" rgba="0.8 0.8 0.8 1" mesh="outer_knuckle"/>
                            <body name="left_inner_finger" pos="0 -0.039592 0.038177">
                              <inertial pos="0 0 0" quat="0.820473 0.339851 -0.17592 0.424708" mass="0.05" diaginertia="0.001002 0.000999 0.000999"/>
                              <geom type="mesh" rgba="0.08 0.08 0.08 1" mesh="inner_finger"/>
                            </body>
                          </body>
                          <body name="left_inner_knuckle" pos="0 -0.007678 0.142297">
                            <inertial pos="0 0 0" quat="0.820473 0.339851 -0.17592 0.424708" mass="0.05" diaginertia="0.001002 0.000999 0.000999"/>
                            <geom type="mesh" rgba="0.8 0.8 0.8 1" mesh="inner_knuckle"/>
                          </body>
                          <body name="right_outer_knuckle" pos="0 0.017178 0.125797" quat="0 0 0 1">
                            <inertial pos="0 0 0" quat="0.820473 0.339851 -0.17592 0.424708" mass="0.05" diaginertia="0.001002 0.000999 0.000999"/>
                            <geom type="mesh" rgba="0.8 0.8 0.8 1" mesh="outer_knuckle"/>
                            <body name="right_inner_finger" pos="0 -0.039592 0.038177">
                              <inertial pos="0 0 0" quat="0.820473 0.339851 -0.17592 0.424708" mass="0.05" diaginertia="0.001002 0.000999 0.000999"/>
                              <geom type="mesh" rgba="0.08 0.08 0.08 1" mesh="inner_finger"/>
                            </body>
                          </body>
                          <body name="right_inner_knuckle" pos="0 0.007678 0.142297" quat="0 0 0 1">
                            <inertial pos="0 0 0" quat="0.820473 0.339851 -0.17592 0.424708" mass="0.05" diaginertia="0.001002 0.000999 0.000999"/>
                            <geom type="mesh" rgba="0.8 0.8 0.8 1" mesh="inner_knuckle"/>
                          </body>
                          <body name="gripper_tcp" pos="0 0 0.218"/>
                        </body>
                      </body>
                    </body>
                  </body>
                </body>
              </body>
            </body>
          </body>
        </body>
      </body>
      <body name="base" quat="0 0 0 1"/>
    </body>
  </worldbody>
</mujoco>
